Workbook

Sheet Dashboard
C2: FERNS N PETALS | AF2: 1,000 orders · 100 customers · 70 products · 301 delivery cities
C4: Sales Analysis — 1 Jan to 29 Dec 2023 | AM4: Every figure recalculates from the two filters below
C7: OCCASION | I7: (All) | T7: CATEGORY | Z7: (All) | AK7: Pick from the dropdowns — charts, tiles and tables all follow
C10: TOTAL REVENUE | M10: AVG ORDER VALUE | W10: REV PER CUSTOMER | AG10: DELIVERY TIME | AQ10: PEAK MONTH | BA10: FESTIVAL SHARE
C11: =Calcs!$B$119 -> 3520984 | M11: =Calcs!$B$122 -> 3520.984 | W11: =Calcs!$B$127 -> 35209.84 | AG11: =Calcs!$B$123 -> 5.5015867 | AQ11: =Calcs!$B$128 -> Aug | BA11: =Calcs!$B$130 -> 0.68244843
C13: =TEXT(Calcs!$B$120,"#,##0")&" orders · "&TEXT(Calcs!$B$121,"#,##0")&" units" -> 1,000 orders · 3,045 units | M13: ="Basket averages "&TEXT(Calcs!$B$121/Calcs!$B$120,"0.00")&" units" -> Basket averages 3.05 units | W13: =TEXT(Calcs!$B$125,"#,##0")&" active buyers" -> 100 active buyers | AG13: =TEXT(Calcs!$B$124,"0%")&" arrive within 7 days" -> 64% arrive within 7 days | AQ13: ="₹"&TEXT(Calcs!$B$129,"##\,##\,##0")&" · "&TEXT(Calcs!$B$126,"#,##0")&" cities" -> ₹7,37,389 · 301 cities | BA13: =TEXT(Calcs!$B$133,"0.0")&"× the quiet-month run rate" -> 4.3× the quiet-month run rate
B16: TIMING | M16: When does the year actually happen?
B37: RHYTHM | M37: What does a week and a day look like?
B57: OCCASION & ASSORTMENT | M57: Which occasion pays, and what sells?
B77: VALUE & REACH | M77: Where does the money concentrate?
B97: CUSTOMERS | M97: Who buys, and how do categories map to occasions?
C100: Highest-value customers | W100: Category × occasion revenue (₹ thousands)
C101: CUSTOMER | L101: REVENUE | Q101: ORDERS | AD101: All Occ. | AH101: Anniv. | AL101: Birthday | AP101: Diwali | AT101: Holi | AX101: Rakhi | BB101: Valentine
C102: =Calcs!$AI$7 -> Samaira Ganesh | M102: =Calcs!$AJ$7 -> 75029 | Q102: =Calcs!$AK$7 -> 16
C103: =Calcs!$AI$8 -> Seher Mann | M103: =Calcs!$AJ$8 -> 70409 | Q103: =Calcs!$AK$8 -> 17 | W103: Cake | AD103: =Calcs!B$109/1000 -> 0 | AH103: =Calcs!C$109/1000 -> 87.176 | AL103: =Calcs!D$109/1000 -> 30.289 | AP103: =Calcs!E$109/1000 -> 0 | AT103: =Calcs!F$109/1000 -> 91.642 | AX103: =Calcs!G$109/1000 -> 53.615 | BB103: =Calcs!H$109/1000 -> 67.14
C104: =Calcs!$AI$9 -> Divit Mahajan | M104: =Calcs!$AJ$9 -> 61294 | Q104: =Calcs!$AK$9 -> 15 | W104: Colors | AD104: =Calcs!B$110/1000 -> 105.732 | AH104: =Calcs!C$110/1000 -> 53.954 | AL104: =Calcs!D$110/1000 -> 157.781 | AP104: =Calcs!E$110/1000 -> 58.253 | AT104: =Calcs!F$110/1000 -> 320.798 | AX104: =Calcs!G$110/1000 -> 158.564 | BB104: =Calcs!H$110/1000 -> 150.563
C105: =Calcs!$AI$10 -> Jhanvi Chowdhury | M105: =Calcs!$AJ$10 -> 59666 | Q105: =Calcs!$AK$10 -> 14 | W105: Mugs | AD105: =Calcs!B$111/1000 -> 11.61 | AH105: =Calcs!C$111/1000 -> 0 | AL105: =Calcs!D$111/1000 -> 38.52 | AP105: =Calcs!E$111/1000 -> 0 | AT105: =Calcs!F$111/1000 -> 69.601 | AX105: =Calcs!G$111/1000 -> 0 | BB105: =Calcs!H$111/1000 -> 81.42
C106: =Calcs!$AI$11 -> Ranbir Loyal | M106: =Calcs!$AJ$11 -> 53082 | Q106: =Calcs!$AK$11 -> 17 | W106: Plants | AD106: =Calcs!B$112/1000 -> 0 | AH106: =Calcs!C$112/1000 -> 116.936 | AL106: =Calcs!D$112/1000 -> 34.268 | AP106: =Calcs!E$112/1000 -> 34.936 | AT106: =Calcs!F$112/1000 -> 16.88 | AX106: =Calcs!G$112/1000 -> 0 | BB106: =Calcs!H$112/1000 -> 9.261
C107: =Calcs!$AI$12 -> Aradhya Batta | M107: =Calcs!$AJ$12 -> 50856 | Q107: =Calcs!$AK$12 -> 14 | W107: Raksha Bandhan | AD107: =Calcs!B$113/1000 -> 60.64 | AH107: =Calcs!C$113/1000 -> 156.384 | AL107: =Calcs!D$113/1000 -> 30.324 | AP107: =Calcs!E$113/1000 -> 42 | AT107: =Calcs!F$113/1000 -> 0 | AX107: =Calcs!G$113/1000 -> 0 | BB107: =Calcs!H$113/1000 -> 8.024
C108: =Calcs!$AI$13 -> Akarsh Ramesh | M108: =Calcs!$AJ$13 -> 50313 | Q108: =Calcs!$AK$13 -> 13 | W108: Soft Toys | AD108: =Calcs!B$114/1000 -> 286.898 | AH108: =Calcs!C$114/1000 -> 75.96 | AL108: =Calcs!D$114/1000 -> 80.64 | AP108: =Calcs!E$114/1000 -> 0 | AT108: =Calcs!F$114/1000 -> 24.131 | AX108: =Calcs!G$114/1000 -> 257.68 | BB108: =Calcs!H$114/1000 -> 15.522
C109: =Calcs!$AI$14 -> Veer Ray | M109: =Calcs!$AJ$14 -> 50151 | Q109: =Calcs!$AK$14 -> 16 | W109: Sweets | AD109: =Calcs!B$115/1000 -> 121.296 | AH109: =Calcs!C$115/1000 -> 184.224 | AL109: =Calcs!D$115/1000 -> 36.372 | AP109: =Calcs!E$115/1000 -> 178.594 | AT109: =Calcs!F$115/1000 -> 51.63 | AX109: =Calcs!G$115/1000 -> 161.726 | BB109: =Calcs!H$115/1000 -> 0
C110: =Calcs!$AI$15 -> Mannat Anand | M110: =Calcs!$AJ$15 -> 49494 | Q110: =Calcs!$AK$15 -> 13
C111: =Calcs!$AI$16 -> Anahita Shankar | M111: =Calcs!$AJ$16 -> 49100 | Q111: =Calcs!$AK$16 -> 13
C114: ="Reading: four festival months carry "&TEXT(Calcs!$B$130,"0%")&" of revenue. A festival month averages ₹"&TEXT(Calcs!$B$131,"##\,##\,##0")&" against ₹"&TEXT(Calcs!$B$132,"##\,##\,##0")&" in a quiet one — "&TEXT(Calcs!$B$133,"0.0")&"× the run rate. Average delivery is "&TEXT(Calcs!$B$123,"0.0")&" days, with "&TEXT(Calcs!$B$124,"0%")&" inside a week." -> Reading: four festival months carry 68% of revenue. A festival month averages ₹6,00,723 against ₹1,39,762 in a quiet one — 4.3× the run rate. Average delivery is 5.5 days, with 64% inside a week.

Sheet Data Dictionary
B2: FNP SALES ANALYSIS — DATA DICTIONARY
B3: Three source files, joined into one fact table on the Model sheet. Revenue is derived, not supplied.
B6: orders.csv
B7: 1,000 rows · 10 fields · the fact table
B9: Field | C9: Type | D9: Key | E9: Notes
B10: Order_ID | C10: integer | D10: PK | E10: Range 1–1000, no duplicates.
B11: Customer_ID | C11: text | D11: FK | E11: Joins to customers.csv.
B12: Product_ID | C12: integer | D12: FK | E12: Joins to products.csv. Always join on this, never on Product_Name.
B13: Quantity | C13: integer | E13: Units of one product, 1–5, near-uniform. Drives basket size.
B14: Order_Date | C14: date | E14: DD-MM-YYYY in the raw file. Parsed explicitly on import — left to Excel, 07-11-2023 reads as 11 July.
B15: Order_Time | C15: time | E15: 24-hour clock. Combined with Order_Date for the hour analysis.
B16: Delivery_Date | C16: date | E16: Runs into January 2024 for late-December orders.
B17: Delivery_Time | C17: time | E17: Paired with Delivery_Date so lead time is measured to the hour.
B18: Location | C18: text | E18: DELIVERY city — 301 distinct. Matches the buyer’s own city in only 0.1% of orders, because gifts ship to the recipient.
B19: Occasion | C19: text | E19: What the order was placed for. Differs from the product’s own Occasion tag.
B22: products.csv
B23: 70 rows · 6 fields · catalogue
B25: Field | C25: Type | D25: Key | E25: Notes
B26: Product_ID | C26: integer | D26: PK | E26: Range 1–70.
B27: Product_Name | C27: text | E27: NOT unique. "Quia Gift" is IDs 21 and 56; "Error Gift" is IDs 65 and 70 — different categories and prices. Grouping by name double-counts them.
B28: Category | C28: text | E28: Cake, Colors, Mugs, Plants, Raksha Bandhan, Soft Toys, Sweets.
B29: Price (INR) | C29: integer | E29: ₹203–₹1,977, median ₹1,170. Unit price, not line total.
B30: Occasion | C30: text | E30: The occasion the item is merchandised for — a catalogue attribute, not a sales fact. The dashboard uses the ORDER occasion instead.
B31: Description | C31: text | E31: Placeholder Latin text. No analytical value.
B34: customers.csv
B35: 100 rows · 7 fields · registered buyers
B37: Field | C37: Type | D37: Key | E37: Notes
B38: Customer_ID | C38: text | D38: PK | E38: C001–C100.
B39: Name | C39: text | E39: Buyer name. Not guaranteed unique — the customer ranking aggregates on Customer_ID.
B40: City | C40: text | E40: Buyer’s home city, 86 distinct. This is NOT the delivery city.
B41: Contact_Number | C41: integer | E41: Stored numerically, so any leading zero is already lost. Treat as text on reload.
B42: Email | C42: text | E42: Free text, not validated against the Name field.
B43: Gender | C43: text | E43: Male / Female, split 51 / 49.
B44: Address | C44: text | E44: Multi-line in the raw file; embedded newline escapes were replaced with commas on import.
B47: Derived fields and assumptions
B49: • Revenue = orders.Quantity × products.Price (INR). There is no revenue column in any source file.
B52: • Lead_Days = (Delivery_Date + Delivery_Time) − (Order_Date + Order_Time), so it is measured to the hour, not rounded to whole days.
B55: • Festival months are Feb (Valentine’s), Mar (Holi), Aug (Raksha Bandhan) and Nov (Diwali) — set on the Lists sheet, column D.
B58: • Price bands and delivery-time buckets are defined on the Lists sheet and applied with LOOKUP, so editing the thresholds there updates every chart.
B61: • The two Dashboard dropdowns write into Calcs!B3 and Calcs!B4, which resolve "(All)" to the wildcard "*". Every SUMIFS and COUNTIFS reads those two cells.
...

Sheet Calcs
A1: CALCULATION LAYER
A2: Every table below is driven by the two dropdowns on the Dashboard. "(All)" becomes the wildcard "*", which SUMIFS matches against any text.
A3: Occasion criteria | B3: =IF(Dashboard!$I$7="(All)","*",Dashboard!$I$7) -> *
A4: Category criteria | B4: =IF(Dashboard!$Z$7="(All)","*",Dashboard!$Z$7) -> *
A6: Revenue by month | L6: All products (keyed on Product_ID) | Q6: Top 10 products | T6: All delivery cities | Y6: Top 10 cities | AC6: All customers | AI6: Top 10 customers
A7: Jan | B7: 1 | C7: =SUMIFS(Model!$N$2:$N$1001,Model!$J$2:$J$1001,$B$3,Model!$L$2:$L$1001,$B$4,Model!$R$2:$R$1001,$B7) -> 95468 | D7: =COUNTIFS(Model!$J$2:$J$1001,$B$3,Model!$L$2:$L$1001,$B$4,Model!$R$2:$R$1001,$B7) -> 34 | E7: =IFERROR($C7/$D7,0) -> 2807.8824 | F7: =INDEX(Lists!$D$2:$D$13,$B7) -> 0 | G7: =IF($F7="",0,1) -> 0 | L7: 1 | M7: =INDEX(Products!$B$2:$B$71,MATCH($L7,Products!$A$2:$A$71,0)) -> Magnam Set | N7: =SUMIFS(Model!$N$2:$N$1001,Model!$J$2:$J$1001,$B$3,Model!$L$2:$L$1001,$B$4,Model!$C$2:$C$1001,$L7) -> 121905 | O7: =$N7+ROW()/1000000 -> 121905 | Q7: =IF($R7=0,"—",INDEX($M$7:$M$76,MATCH(LARGE($O$7:$O$76,1),$O$7:$O$76,0))) -> Magnam Set | R7: =INDEX($N$7:$N$76,MATCH(LARGE($O$7:$O$76,1),$O$7:$O$76,0)) -> 121905 | T7: Adoni | U7: =COUNTIFS(Model!$J$2:$J$1001,$B$3,Model!$L$2:$L$1001,$B$4,Model!$I$2:$I$1001,$T7) -> 3 | V7: =SUMIFS(Model!$N$2:$N$1001,Model!$J$2:$J$1001,$B$3,Model!$L$2:$L$1001,$B$4,Model!$I$2:$I$1001,$T7) -> 9419 | W7: =$U7+$V7/1000000000+ROW()/1000000000000 -> 3.0000094 | Y7: =IF($Z7=0,"—",INDEX($T$7:$T$307,MATCH(LARGE($W$7:$W$307,1),$W$7:$W$307,0))) -> Ghaziabad | Z7: =INDEX($U$7:$U$307,MATCH(LARGE($W$7:$W$307,1),$W$7:$W$307,0)) -> 9 | AA7: =INDEX($V$7:$V$307,MATCH(LARGE($W$7:$W$307,1),$W$7:$W$307,0)) -> 37820 | AC7: C001 | AD7: =INDEX(Customers!$B$2:$B$101,MATCH($AC7,Customers!$A$2:$A$101,0)) -> Tara Krishnan | AE7: =SUMIFS(Model!$N$2:$N$1001,Model!$J$2:$J$1001,$B$3,Model!$L$2:$L$1001,$B$4,Model!$B$2:$B$1001,$AC7) -> 9095 | AF7: =COUNTIFS(Model!$J$2:$J$1001,$B$3,Model!$L$2:$L$1001,$B$4,Model!$B$2:$B$1001,$AC7) -> 5 | AG7: =$AE7+ROW()/1000000 -> 9095 | AI7: =IF($AJ7=0,"—",INDEX($AD$7:$AD$106,MATCH(LARGE($AG$7:$AG$106,1),$AG$7:$AG$106,0))) -> Samaira Ganesh | AJ7: =INDEX($AE$7:$AE$106,MATCH(LARGE($AG$7:$AG$106,1),$AG$7:$AG$106,0)) -> 75029 | AK7: =INDEX($AF$7:$AF$106,MATCH(LARGE($AG$7:$AG$106,1),$AG$7:$AG$106,0)) -> 16
A8: Feb | B8: 2 | C8: =SUMIFS(Model!$N$2:$N$1001,Model!$J$2:$J$1001,$B$3,Model!$L$2:$L$1001,$B$4,Model!$R$2:$R$1001,$B8) -> 704509 | D8: =COUNTIFS(Model!$J$2:$J$1001,$B$3,Model!$L$2:$L$1001,$B$4,Model!$R$2:$R$1001,$B8) -> 213 | E8: =IFERROR($C8/$D8,0) -> 3307.554 | F8: =INDEX(Lists!$D$2:$D$13,$B8) -> Valentine's Day | G8: =IF($F8="",0,1) -> 1 | L8: 2 | M8: =INDEX(Products!$B$2:$B$71,MATCH($L8,Products!$A$2:$A$71,0)) -> Voluptas Box | N8: =SUMIFS(Model!$N$2:$N$1001,Model!$J$2:$J$1001,$B$3,Model!$L$2:$L$1001,$B$4,Model!$C$2:$C$1001,$L8) -> 9261 | O8: =$N8+ROW()/1000000 -> 9261 | Q8: =IF($R8=0,"—",INDEX($M$7:$M$76,MATCH(LARGE($O$7:$O$76,2),$O$7:$O$76,0))) -> Dolores Gift | R8: =INDEX($N$7:$N$76,MATCH(LARGE($O$7:$O$76,2),$O$7:$O$76,0)) -> 106624 | T8: Agartala | U8: =COUNTIFS(Model!$J$2:$J$1001,$B$3,Model!$L$2:$L$1001,$B$4,Model!$I$2:$I$1001,$T8) -> 4 | V8: =SUMIFS(Model!$N$2:$N$1001,Model!$J$2:$J$1001,$B$3,Model!$L$2:$L$1001,$B$4,Model!$I$2:$I$1001,$T8) -> 13403 | W8: =$U8+$V8/1000000000+ROW()/1000000000000 -> 4.0000134 | Y8: =IF($Z8=0,"—",INDEX($T$7:$T$307,MATCH(LARGE($W$7:$W$307,2),$W$7:$W$307,0))) -> Bareilly | Z8: =INDEX($U$7:$U$307,MATCH(LARGE($W$7:$W$307,2),$W$7:$W$307,0)) -> 9 | AA8: =INDEX($V$7:$V$307,MATCH(LARGE($W$7:$W$307,2),$W$7:$W$307,0)) -> 30626 | AC8: C002 | AD8: =INDEX(Customers!$B$2:$B$101,MATCH($AC8,Customers!$A$2:$A$101,0)) -> Myra Edwin | AE8: =SUMIFS(Model!$N$2:$N$1001,Model!$J$2:$J$1001,$B$3,Model!$L$2:$L$1001,$B$4,Model!$B$2:$B$1001,$AC8) -> 23860 | AF8: =COUNTIFS(Model!$J$2:$J$1001,$B$3,Model!$L$2:$L$1001,$B$4,Model!$B$2:$B$1001,$AC8) -> 8 | AG8: =$AE8+ROW()/1000000 -> 23860 | AI8: =IF($AJ8=0,"—",INDEX($AD$7:$AD$106,MATCH(LARGE($AG$7:$AG$106,2),$AG$7:$AG$106,0))) -> Seher Mann | AJ8: =INDEX($AE$7:$AE$106,MATCH(LARGE($AG$7:$AG$106,2),$AG$7:$AG$106,0)) -> 70409 | AK8: =INDEX($AF$7:$AF$106,MATCH(LARGE($AG$7:$AG$106,2),$AG$7:$AG$106,0)) -> 17
A9: Mar | B9: 3 | C9: =SUMIFS(Model!$N$2:$N$1001,Model!$J$2:$J$1001,$B$3,Model!$L$2:$L$1001,$B$4,Model!$R$2:$R$1001,$B9) -> 511823 | D9: =COUNTIFS(Model!$J$2:$J$1001,$B$3,Model!$L$2:$L$1001,$B$4,Model!$R$2:$R$1001,$B9) -> 166 | E9: =IFERROR($C9/$D9,0) -> 3083.2711 | F9: =INDEX(Lists!$D$2:$D$13,$B9) -> Holi | G9: =IF($F9="",0,1) -> 1 | L9: 3 | M9: =INDEX(Products!$B$2:$B$71,MATCH($L9,Products!$A$2:$A$71,0)) -> Eius Gift | N9: =SUMIFS(Model!$N$2:$N$1001,Model!$J$2:$J$1001,$B$3,Model!$L$2:$L$1001,$B$4,Model!$C$2:$C$1001,$L9) -> 85904 | O9: =$N9+ROW()/1000000 -> 85904 | Q9: =IF($R9=0,"—",INDEX($M$7:$M$76,MATCH(LARGE($O$7:$O$76,3),$O$7:$O$76,0))) -> Harum Pack | R9: =INDEX($N$7:$N$76,MATCH(LARGE($O$7:$O$76,3),$O$7:$O$76,0)) -> 101556 | T9: Agra | U9: =COUNTIFS(Model!$J$2:$J$1001,$B$3,Model!$L$2:$L$1001,$B$4,Model!$I$2:$I$1001,$T9) -> 3 | V9: =SUMIFS(Model!$N$2:$N$1001,Model!$J$2:$J$1001,$B$3,Model!$L$2:$L$1001,$B$4,Model!$I$2:$I$1001,$T9) -> 6828 | W9: =$U9+$V9/1000000000+ROW()/1000000000000 -> 3.0000068 | Y9: =IF($Z9=0,"—",INDEX($T$7:$T$307,MATCH(LARGE($W$7:$W$307,3),$W$7:$W$307,0))) -> Bhilai | Z9: =INDEX($U$7:$U$307,MATCH(LARGE($W$7:$W$307,3),$W$7:$W$307,0)) -> 8 | AA9: =INDEX($V$7:$V$307,MATCH(LARGE($W$7:$W$307,3),$W$7:$W$307,0)) -> 36141 | AC9: C003 | AD9: =INDEX(Customers!$B$2:$B$101,MATCH($AC9,Customers!$A$2:$A$101,0)) -> Jayesh Lanka | AE9: =SUMIFS(Model!$N$2:$N$1001,Model!$J$2:$J$1001,$B$3,Model!$L$2:$L$1001,$B$4,Model!$B$2:$B$1001,$AC9) -> 34871 | AF9: =COUNTIFS(Model!$J$2:$J$1001,$B$3,Model!$L$2:$L$1001,$B$4,Model!$B$2:$B$1001,$AC9) -> 10 | AG9: =$AE9+ROW()/1000000 -> 34871 | AI9: =IF($AJ9=0,"—",INDEX($AD$7:$AD$106,MATCH(LARGE($AG$7:$AG$106,3),$AG$7:$AG$106,0))) -> Divit Mahajan | AJ9: =INDEX($AE$7:$AE$106,MATCH(LARGE($AG$7:$AG$106,3),$AG$7:$AG$106,0)) -> 61294 | AK9: =INDEX($AF$7:$AF$106,MATCH(LARGE($AG$7:$AG$106,3),$AG$7:$AG$106,0)) -> 15
A10: Apr | B10: 4 | C10: =SUMIFS(Model!$N$2:$N$1001,Model!$J$2:$J$1001,$B$3,Model!$L$2:$L$1001,$B$4,Model!$R$2:$R$1001,$B10) -> 140393 | D10: =COUNTIFS(Model!$J$2:$J$1001,$B$3,Model!$L$2:$L$1001,$B$4,Model!$R$2:$R$1001,$B10) -> 40 | E10: =IFERROR($C10/$D10,0) -> 3509.825 | F10: =INDEX(Lists!$D$2:$D$13,$B10) -> 0 | G10: =IF($F10="",0,1) -> 0 | L10: 4 | M10: =INDEX(Products!$B$2:$B$71,MATCH($L10,Products!$A$2:$A$71,0)) -> Accusantium Set | N10: =SUMIFS(Model!$N$2:$N$1001,Model!$J$2:$J$1001,$B$3,Model!$L$2:$L$1001,$B$4,Model!$C$2:$C$1001,$L10) -> 61149 | O10: =$N10+ROW()/1000000 -> 61149 | Q10: =IF($R10=0,"—",INDEX($M$7:$M$76,MATCH(LARGE($O$7:$O$76,4),$O$7:$O$76,0))) -> Deserunt Box | R10: =INDEX($N$7:$N$76,MATCH(LARGE($O$7:$O$76,4),$O$7:$O$76,0)) -> 97665 | T10: Ahmedabad | U10: =COUNTIFS(Model!$J$2:$J$1001,$B$3,Model!$L$2:$L$1001,$B$4,Model!$I$2:$I$1001,$T10) -> 6 | V10: =SUMIFS(Model!$N$2:$N$1001,Model!$J$2:$J$1001,$B$3,Model!$L$2:$L$1001,$B$4,Model!$I$2:$I$1001,$T10) -> 29560 | W10: =$U10+$V10/1000000000+ROW()/1000000000000 -> 6.0000296 | Y10: =IF($Z10=0,"—",INDEX($T$7:$T$307,MATCH(LARGE($W$7:$W$307,4),$W$7:$W$307,0))) -> Hazaribagh | Z10: =INDEX($U$7:$U$307,MATCH(LARGE($W$7:$W$307,4),$W$7:$W$307,0)) -> 7 | AA10: =INDEX($V$7:$V$307,MATCH(LARGE($W$7:$W$307,4),$W$7:$W$307,0)) -> 34167 | AC10: C004 | AD10: =INDEX(Customers!$B$2:$B$101,MATCH($AC10,Customers!$A$2:$A$101,0)) -> Tarini Bava | AE10: =SUMIFS(Model!$N$2:$N$1001,Model!$J$2:$J$1001,$B$3,Model!$L$2:$L$1001,$B$4,Model!$B$2:$B$1001,$AC10) -> 35894 | AF10: =COUNTIFS(Model!$J$2:$J$1001,$B$3,Model!$L$2:$L$1001,$B$4,Model!$B$2:$B$1001,$AC10) -> 11 | AG10: =$AE10+ROW()/1000000 -> 35894 | AI10: =IF($AJ10=0,"—",INDEX($AD$7:$AD$106,MATCH(LARGE($AG$7:$AG$106,4),$AG$7:$AG$106,0))) -> Jhanvi Chowdhury | AJ10: =INDEX($AE$7:$AE$106,MATCH(LARGE($AG$7:$AG$106,4),$AG$7:$AG$106,0)) -> 59666 | AK10: =INDEX($AF$7:$AF$106,MATCH(LARGE($AG$7:$AG$106,4),$AG$7:$AG$106,0)) -> 14
A11: May | B11: 5 | C11: =SUMIFS(Model!$N$2:$N$1001,Model!$J$2:$J$1001,$B$3,Model!$L$2:$L$1001,$B$4,Model!$R$2:$R$1001,$B11) -> 150346 | D11: =COUNTIFS(Model!$J$2:$J$1001,$B$3,Model!$L$2:$L$1001,$B$4,Model!$R$2:$R$1001,$B11) -> 43 | E11: =IFERROR($C11/$D11,0) -> 3496.4186 | F11: =INDEX(Lists!$D$2:$D$13,$B11) -> 0 | G11: =IF($F11="",0,1) -> 0 | L11: 5 | M11: =INDEX(Products!$B$2:$B$71,MATCH($L11,Products!$A$2:$A$71,0)) -> Natus Gift | N11: =SUMIFS(Model!$N$2:$N$1001,Model!$J$2:$J$1001,$B$3,Model!$L$2:$L$1001,$B$4,Model!$C$2:$C$1001,$L11) -> 31768 | O11: =$N11+ROW()/1000000 -> 31768 | Q11: =IF($R11=0,"—",INDEX($M$7:$M$76,MATCH(LARGE($O$7:$O$76,5),$O$7:$O$76,0))) -> Nostrum Box | R11: =INDEX($N$7:$N$76,MATCH(LARGE($O$7:$O$76,5),$O$7:$O$76,0)) -> 97656 | T11: Ahmednagar | U11: =COUNTIFS(Model!$J$2:$J$1001,$B$3,Model!$L$2:$L$1001,$B$4,Model!$I$2:$I$1001,$T11) -> 3 | V11: =SUMIFS(Model!$N$2:$N$1001,Model!$J$2:$J$1001,$B$3,Model!$L$2:$L$1001,$B$4,Model!$I$2:$I$1001,$T11) -> 9174 | W11: =$U11+$V11/1000000000+ROW()/1000000000000 -> 3.0000092 | Y11: =IF($Z11=0,"—",INDEX($T$7:$T$307,MATCH(LARGE($W$7:$W$307,5),$W$7:$W$307,0))) -> Satara | Z11: =INDEX($U$7:$U$307,MATCH(LARGE($W$7:$W$307,5),$W$7:$W$307,0)) -> 7 | AA11: =INDEX($V$7:$V$307,MATCH(LARGE($W$7:$W$307,5),$W$7:$W$307,0)) -> 27857 | AC11: C005 | AD11: =INDEX(Customers!$B$2:$B$101,MATCH($AC11,Customers!$A$2:$A$101,0)) -> Hiran Kaul | AE11: =SUMIFS(Model!$N$2:$N$1001,Model!$J$2:$J$1001,$B$3,Model!$L$2:$L$1001,$B$4,Model!$B$2:$B$1001,$AC11) -> 8403 | AF11: =COUNTIFS(Model!$J$2:$J$1001,$B$3,Model!$L$2:$L$1001,$B$4,Model!$B$2:$B$1001,$AC11) -> 4 | AG11: =$AE11+ROW()/1000000 -> 8403 | AI11: =IF($AJ11=0,"—",INDEX($AD$7:$AD$106,MATCH(LARGE($AG$7:$AG$106,5),$AG$7:$AG$106,0))) -> Ranbir Loyal | AJ11: =INDEX($AE$7:$AE$106,MATCH(LARGE($AG$7:$AG$106,5),$AG$7:$AG$106,0)) -> 53082 | AK11: =INDEX($AF$7:$AF$106,MATCH(LARGE($AG$7:$AG$106,5),$AG$7:$AG$106,0)) -> 17
A12: Jun | B12: 6 | C12: =SUMIFS(Model!$N$2:$N$1001,Model!$J$2:$J$1001,$B$3,Model!$L$2:$L$1001,$B$4,Model!$R$2:$R$1001,$B12) -> 157913 | D12: =COUNTIFS(Model!$J$2:$J$1001,$B$3,Model!$L$2:$L$1001,$B$4,Model!$R$2:$R$1001,$B12) -> 45 | E12: =IFERROR($C12/$D12,0) -> 3509.1778 | F12: =INDEX(Lists!$D$2:$D$13,$B12) -> 0 | G12: =IF($F12="",0,1) -> 0 | L12: 6 | M12: =INDEX(Products!$B$2:$B$71,MATCH($L12,Products!$A$2:$A$71,0)) -> Quos Box | N12: =SUMIFS(Model!$N$2:$N$1001,Model!$J$2:$J$1001,$B$3,Model!$L$2:$L$1001,$B$4,Model!$C$2:$C$1001,$L12) -> 56712 | O12: =$N12+ROW()/1000000 -> 56712 | Q12: =IF($R12=0,"—",INDEX($M$7:$M$76,MATCH(LARGE($O$7:$O$76,6),$O$7:$O$76,0))) -> Exercitationem Pack | R12: =INDEX($N$7:$N$76,MATCH(LARGE($O$7:$O$76,6),$O$7:$O$76,0)) -> 96701 | T12: Aizawl | U12: =COUNTIFS(Model!$J$2:$J$1001,$B$3,Model!$L$2:$L$1001,$B$4,Model!$I$2:$I$1001,$T12) -> 1 | V12: =SUMIFS(Model!$N$2:$N$1001,Model!$J$2:$J$1001,$B$3,Model!$L$2:$L$1001,$B$4,Model!$I$2:$I$1001,$T12) -> 289 | W12: =$U12+$V12/1000000000+ROW()/1000000000000 -> 1.0000003 | Y12: =IF($Z12=0,"—",INDEX($T$7:$T$307,MATCH(LARGE($W$7:$W$307,6),$W$7:$W$307,0))) -> Khammam | Z12: =INDEX($U$7:$U$307,MATCH(LARGE($W$7:$W$307,6),$W$7:$W$307,0)) -> 7 | AA12: =INDEX($V$7:$V$307,MATCH(LARGE($W$7:$W$307,6),$W$7:$W$307,0)) -> 27624 | AC12: C006 | AD12: =INDEX(Customers!$B$2:$B$101,MATCH($AC12,Customers!$A$2:$A$101,0)) -> Rania Mann | AE12: =SUMIFS(Model!$N$2:$N$1001,Model!$J$2:$J$1001,$B$3,Model!$L$2:$L$1001,$B$4,Model!$B$2:$B$1001,$AC12) -> 35959 | AF12: =COUNTIFS(Model!$J$2:$J$1001,$B$3,Model!$L$2:$L$1001,$B$4,Model!$B$2:$B$1001,$AC12) -> 10 | AG12: =$AE12+ROW()/1000000 -> 35959 | AI12: =IF($AJ12=0,"—",INDEX($AD$7:$AD$106,MATCH(LARGE($AG$7:$AG$106,6),$AG$7:$AG$106,0))) -> Aradhya Batta | AJ12: =INDEX($AE$7:$AE$106,MATCH(LARGE($AG$7:$AG$106,6),$AG$7:$AG$106,0)) -> 50856 | AK12: =INDEX($AF$7:$AF$106,MATCH(LARGE($AG$7:$AG$106,6),$AG$7:$AG$106,0)) -> 14
A13: Jul | B13: 7 | C13: =SUMIFS(Model!$N$2:$N$1001,Model!$J$2:$J$1001,$B$3,Model!$L$2:$L$1001,$B$4,Model!$R$2:$R$1001,$B13) -> 135826 | D13: =COUNTIFS(Model!$J$2:$J$1001,$B$3,Model!$L$2:$L$1001,$B$4,Model!$R$2:$R$1001,$B13) -> 39 | E13: =IFERROR($C13/$D13,0) -> 3482.7179 | F13: =INDEX(Lists!$D$2:$D$13,$B13) -> 0 | G13: =IF($F13="",0,1) -> 0 | L13: 7 | M13: =INDEX(Products!$B$2:$B$71,MATCH($L13,Products!$A$2:$A$71,0)) -> Quos Set | N13: =SUMIFS(Model!$N$2:$N$1001,Model!$J$2:$J$1001,$B$3,Model!$L$2:$L$1001,$B$4,Model!$C$2:$C$1001,$L13) -> 24131 | O13: =$N13+ROW()/1000000 -> 24131 | Q13: =IF($R13=0,"—",INDEX($M$7:$M$76,MATCH(LARGE($O$7:$O$76,7),$O$7:$O$76,0))) -> Nam Gift | R13: =INDEX($N$7:$N$76,MATCH(LARGE($O$7:$O$76,7),$O$7:$O$76,0)) -> 91385 | T13: Ajmer | U13: =COUNTIFS(Model!$J$2:$J$1001,$B$3,Model!$L$2:$L$1001,$B$4,Model!$I$2:$I$1001,$T13) -> 2 | V13: =SUMIFS(Model!$N$2:$N$1001,Model!$J$2:$J$1001,$B$3,Model!$L$2:$L$1001,$B$4,Model!$I$2:$I$1001,$T13) -> 13423 | W13: =$U13+$V13/1000000000+ROW()/1000000000000 -> 2.0000134 | Y13: =IF($Z13=0,"—",INDEX($T$7:$T$307,MATCH(LARGE($W$7:$W$307,7),$W$7:$W$307,0))) -> Darbhanga | Z13: =INDEX($U$7:$U$307,MATCH(LARGE($W$7:$W$307,7),$W$7:$W$307,0)) -> 7 | AA13: =INDEX($V$7:$V$307,MATCH(LARGE($W$7:$W$307,7),$W$7:$W$307,0)) -> 25662 | AC13: C007 | AD13: =INDEX(Customers!$B$2:$B$101,MATCH($AC13,Customers!$A$2:$A$101,0)) -> Jayant Kamdar | AE13: =SUMIFS(Model!$N$2:$N$1001,Model!$J$2:$J$1001,$B$3,Model!$L$2:$L$1001,$B$4,Model!$B$2:$B$1001,$AC13) -> 34438 | AF13: =COUNTIFS(Model!$J$2:$J$1001,$B$3,Model!$L$2:$L$1001,$B$4,Model!$B$2:$B$1001,$AC13) -> 12 | AG13: =$AE13+ROW()/1000000 -> 34438 | AI13: =IF($AJ13=0,"—",INDEX($AD$7:$AD$106,MATCH(LARGE($AG$7:$AG$106,7),$AG$7:$AG$106,0))) -> Akarsh Ramesh | AJ13: =INDEX($AE$7:$AE$106,MATCH(LARGE($AG$7:$AG$106,7),$AG$7:$AG$106,0)) -> 50313 | AK13: =INDEX($AF$7:$AF$106,MATCH(LARGE($AG$7:$AG$106,7),$AG$7:$AG$106,0)) -> 13
A14: Aug | B14: 8 | C14: =SUMIFS(Model!$N$2:$N$1001,Model!$J$2:$J$1001,$B$3,Model!$L$2:$L$1001,$B$4,Model!$R$2:$R$1001,$B14) -> 737389 | D14: =COUNTIFS(Model!$J$2:$J$1001,$B$3,Model!$L$2:$L$1001,$B$4,Model!$R$2:$R$1001,$B14) -> 165 | E14: =IFERROR($C14/$D14,0) -> 4469.0242 | F14: =INDEX(Lists!$D$2:$D$13,$B14) -> Raksha Bandhan | G14: =IF($F14="",0,1) -> 1 | L14: 8 | M14: =INDEX(Products!$B$2:$B$71,MATCH($L14,Products!$A$2:$A$71,0)) -> Qui Box | N14: =SUMIFS(Model!$N$2:$N$1001,Model!$J$2:$J$1001,$B$3,Model!$L$2:$L$1001,$B$4,Model!$C$2:$C$1001,$L14) -> 9576 | O14: =$N14+ROW()/1000000 -> 9576 | Q14: =IF($R14=0,"—",INDEX($M$7:$M$76,MATCH(LARGE($O$7:$O$76,8),$O$7:$O$76,0))) -> Dignissimos Pack | R14: =INDEX($N$7:$N$76,MATCH(LARGE($O$7:$O$76,8),$O$7:$O$76,0)) -> 90036 | T14: Akola | U14: =COUNTIFS(Model!$J$2:$J$1001,$B$3,Model!$L$2:$L$1001,$B$4,Model!$I$2:$I$1001,$T14) -> 3 | V14: =SUMIFS(Model!$N$2:$N$1001,Model!$J$2:$J$1001,$B$3,Model!$L$2:$L$1001,$B$4,Model!$I$2:$I$1001,$T14) -> 9541 | W14: =$U14+$V14/1000000000+ROW()/1000000000000 -> 3.0000095 | Y14: =IF($Z14=0,"—",INDEX($T$7:$T$307,MATCH(LARGE($W$7:$W$307,8),$W$7:$W$307,0))) -> Lucknow | Z14: =INDEX($U$7:$U$307,MATCH(LARGE($W$7:$W$307,8),$W$7:$W$307,0)) -> 7 | AA14: =INDEX($V$7:$V$307,MATCH(LARGE($W$7:$W$307,8),$W$7:$W$307,0)) -> 25405 | AC14: C008 | AD14: =INDEX(Customers!$B$2:$B$101,MATCH($AC14,Customers!$A$2:$A$101,0)) -> Veer Ray | AE14: =SUMIFS(Model!$N$2:$N$1001,Model!$J$2:$J$1001,$B$3,Model!$L$2:$L$1001,$B$4,Model!$B$2:$B$1001,$AC14) -> 50151 | AF14: =COUNTIFS(Model!$J$2:$J$1001,$B$3,Model!$L$2:$L$1001,$B$4,Model!$B$2:$B$1001,$AC14) -> 16 | AG14: =$AE14+ROW()/1000000 -> 50151 | AI14: =IF($AJ14=0,"—",INDEX($AD$7:$AD$106,MATCH(LARGE($AG$7:$AG$106,8),$AG$7:$AG$106,0))) -> Veer Ray | AJ14: =INDEX($AE$7:$AE$106,MATCH(LARGE($AG$7:$AG$106,8),$AG$7:$AG$106,0)) -> 50151 | AK14: =INDEX($AF$7:$AF$106,MATCH(LARGE($AG$7:$AG$106,8),$AG$7:$AG$106,0)) -> 16
A15: Sep | B15: 9 | C15: =SUMIFS(Model!$N$2:$N$1001,Model!$J$2:$J$1001,$B$3,Model!$L$2:$L$1001,$B$4,Model!$R$2:$R$1001,$B15) -> 136938 | D15: =COUNTIFS(Model!$J$2:$J$1001,$B$3,Model!$L$2:$L$1001,$B$4,Model!$R$2:$R$1001,$B15) -> 40 | E15: =IFERROR($C15/$D15,0) -> 3423.45 | F15: =INDEX(Lists!$D$2:$D$13,$B15) -> 0 | G15: =IF($F15="",0,1) -> 0 | L15: 9 | M15: =INDEX(Products!$B$2:$B$71,MATCH($L15,Products!$A$2:$A$71,0)) -> Aperiam Box | N15: =SUMIFS(Model!$N$2:$N$1001,Model!$J$2:$J$1001,$B$3,Model!$L$2:$L$1001,$B$4,Model!$C$2:$C$1001,$L15) -> 89880 | O15: =$N15+ROW()/1000000 -> 89880 | Q15: =IF($R15=0,"—",INDEX($M$7:$M$76,MATCH(LARGE($O$7:$O$76,9),$O$7:$O$76,0))) -> Aperiam Box | R15: =INDEX($N$7:$N$76,MATCH(LARGE($O$7:$O$76,9),$O$7:$O$76,0)) -> 89880 | T15: Alappuzha | U15: =COUNTIFS(Model!$J$2:$J$1001,$B$3,Model!$L$2:$L$1001,$B$4,Model!$I$2:$I$1001,$T15) -> 2 | V15: =SUMIFS(Model!$N$2:$N$1001,Model!$J$2:$J$1001,$B$3,Model!$L$2:$L$1001,$B$4,Model!$I$2:$I$1001,$T15) -> 6868 | W15: =$U15+$V15/1000000000+ROW()/1000000000000 -> 2.0000069 | Y15: =IF($Z15=0,"—",INDEX($T$7:$T$307,MATCH(LARGE($W$7:$W$307,9),$W$7:$W$307,0))) -> Ozhukarai | Z15: =INDEX($U$7:$U$307,MATCH(LARGE($W$7:$W$307,9),$W$7:$W$307,0)) -> 7 | AA15: =INDEX($V$7:$V$307,MATCH(LARGE($W$7:$W$307,9),$W$7:$W$307,0)) -> 23395 | AC15: C009 | AD15: =INDEX(Customers!$B$2:$B$101,MATCH($AC15,Customers!$A$2:$A$101,0)) -> Ritvik Borah | AE15: =SUMIFS(Model!$N$2:$N$1001,Model!$J$2:$J$1001,$B$3,Model!$L$2:$L$1001,$B$4,Model!$B$2:$B$1001,$AC15) -> 42882 | AF15: =COUNTIFS(Model!$J$2:$J$1001,$B$3,Model!$L$2:$L$1001,$B$4,Model!$B$2:$B$1001,$AC15) -> 12 | AG15: =$AE15+ROW()/1000000 -> 42882 | AI15: =IF($AJ15=0,"—",INDEX($AD$7:$AD$106,MATCH(LARGE($AG$7:$AG$106,9),$AG$7:$AG$106,0))) -> Mannat Anand | AJ15: =INDEX($AE$7:$AE$106,MATCH(LARGE($AG$7:$AG$106,9),$AG$7:$AG$106,0)) -> 49494 | AK15: =INDEX($AF$7:$AF$106,MATCH(LARGE($AG$7:$AG$106,9),$AG$7:$AG$106,0)) -> 13
A16: Oct | B16: 10 | C16: =SUMIFS(Model!$N$2:$N$1001,Model!$J$2:$J$1001,$B$3,Model!$L$2:$L$1001,$B$4,Model!$R$2:$R$1001,$B16) -> 151619 | D16: =COUNTIFS(Model!$J$2:$J$1001,$B$3,Model!$L$2:$L$1001,$B$4,Model!$R$2:$R$1001,$B16) -> 39 | E16: =IFERROR($C16/$D16,0) -> 3887.6667 | F16: =INDEX(Lists!$D$2:$D$13,$B16) -> 0 | G16: =IF($F16="",0,1) -> 0 | L16: 10 | M16: =INDEX(Products!$B$2:$B$71,MATCH($L16,Products!$A$2:$A$71,0)) -> Accusantium Gift | N16: =SUMIFS(Model!$N$2:$N$1001,Model!$J$2:$J$1001,$B$3,Model!$L$2:$L$1001,$B$4,Model!$C$2:$C$1001,$L16) -> 10619 | O16: =$N16+ROW()/1000000 -> 10619 | Q16: =IF($R16=0,"—",INDEX($M$7:$M$76,MATCH(LARGE($O$7:$O$76,10),$O$7:$O$76,0))) -> Expedita Gift | R16: =INDEX($N$7:$N$76,MATCH(LARGE($O$7:$O$76,10),$O$7:$O$76,0)) -> 88944 | T16: Aligarh | U16: =COUNTIFS(Model!$J$2:$J$1001,$B$3,Model!$L$2:$L$1001,$B$4,Model!$I$2:$I$1001,$T16) -> 2 | V16: =SUMIFS(Model!$N$2:$N$1001,Model!$J$2:$J$1001,$B$3,Model!$L$2:$L$1001,$B$4,Model!$I$2:$I$1001,$T16) -> 11303 | W16: =$U16+$V16/1000000000+ROW()/1000000000000 -> 2.0000113 | Y16: =IF($Z16=0,"—",INDEX($T$7:$T$307,MATCH(LARGE($W$7:$W$307,10),$W$7:$W$307,0))) -> Sirsa | Z16: =INDEX($U$7:$U$307,MATCH(LARGE($W$7:$W$307,10),$W$7:$W$307,0)) -> 7 | AA16: =INDEX($V$7:$V$307,MATCH(LARGE($W$7:$W$307,10),$W$7:$W$307,0)) -> 22638 | AC16: C010 | AD16: =INDEX(Customers!$B$2:$B$101,MATCH($AC16,Customers!$A$2:$A$101,0)) -> Darshit Dave | AE16: =SUMIFS(Model!$N$2:$N$1001,Model!$J$2:$J$1001,$B$3,Model!$L$2:$L$1001,$B$4,Model!$B$2:$B$1001,$AC16) -> 24931 | AF16: =COUNTIFS(Model!$J$2:$J$1001,$B$3,Model!$L$2:$L$1001,$B$4,Model!$B$2:$B$1001,$AC16) -> 8 | AG16: =$AE16+ROW()/1000000 -> 24931 | AI16: =IF($AJ16=0,"—",INDEX($AD$7:$AD$106,MATCH(LARGE($AG$7:$AG$106,10),$AG$7:$AG$106,0))) -> Anahita Shankar | AJ16: =INDEX($AE$7:$AE$106,MATCH(LARGE($AG$7:$AG$106,10),$AG$7:$AG$106,0)) -> 49100 | AK16: =INDEX($AF$7:$AF$106,MATCH(LARGE($AG$7:$AG$106,10),$AG$7:$AG$106,0)) -> 13
A17: Nov | B17: 11 | C17: =SUMIFS(Model!$N$2:$N$1001,Model!$J$2:$J$1001,$B$3,Model!$L$2:$L$1001,$B$4,Model!$R$2:$R$1001,$B17) -> 449169 | D17: =COUNTIFS(Model!$J$2:$J$1001,$B$3,Model!$L$2:$L$1001,$B$4,Model!$R$2:$R$1001,$B17) -> 134 | E17: =IFERROR($C17/$D17,0) -> 3352.0075 | F17: =INDEX(Lists!$D$2:$D$13,$B17) -> Diwali | G17: =IF($F17="",0,1) -> 1 | L17: 11 | M17: =INDEX(Products!$B$2:$B$71,MATCH($L17,Products!$A$2:$A$71,0)) -> Maxime Set | N17: =SUMIFS(Model!$N$2:$N$1001,Model!$J$2:$J$1001,$B$3,Model!$L$2:$L$1001,$B$4,Model!$C$2:$C$1001,$L17) -> 29592 | O17: =$N17+ROW()/1000000 -> 29592 | T17: Allahabad | U17: =COUNTIFS(Model!$J$2:$J$1001,$B$3,Model!$L$2:$L$1001,$B$4,Model!$I$2:$I$1001,$T17) -> 5 | V17: =SUMIFS(Model!$N$2:$N$1001,Model!$J$2:$J$1001,$B$3,Model!$L$2:$L$1001,$B$4,Model!$I$2:$I$1001,$T17) -> 23405 | W17: =$U17+$V17/1000000000+ROW()/1000000000000 -> 5.0000234 | AC17: C011 | AD17: =INDEX(Customers!$B$2:$B$101,MATCH($AC17,Customers!$A$2:$A$101,0)) -> Lagan Kapoor | AE17: =SUMIFS(Model!$N$2:$N$1001,Model!$J$2:$J$1001,$B$3,Model!$L$2:$L$1001,$B$4,Model!$B$2:$B$1001,$AC17) -> 15042 | AF17: =COUNTIFS(Model!$J$2:$J$1001,$B$3,Model!$L$2:$L$1001,$B$4,Model!$B$2:$B$1001,$AC17) -> 7 | AG17: =$AE17+ROW()/1000000 -> 15042
A18: Dec | B18: 12 | C18: =SUMIFS(Model!$N$2:$N$1001,Model!$J$2:$J$1001,$B$3,Model!$L$2:$L$1001,$B$4,Model!$R$2:$R$1001,$B18) -> 149591 | D18: =COUNTIFS(Model!$J$2:$J$1001,$B$3,Model!$L$2:$L$1001,$B$4,Model!$R$2:$R$1001,$B18) -> 42 | E18: =IFERROR($C18/$D18,0) -> 3561.6905 | F18: =INDEX(Lists!$D$2:$D$13,$B18) -> 0 | G18: =IF($F18="",0,1) -> 0 | L18: 12 | M18: =INDEX(Products!$B$2:$B$71,MATCH($L18,Products!$A$2:$A$71,0)) -> Non Set | N18: =SUMIFS(Model!$N$2:$N$1001,Model!$J$2:$J$1001,$B$3,Model!$L$2:$L$1001,$B$4,Model!$C$2:$C$1001,$L18) -> 32928 | O18: =$N18+ROW()/1000000 -> 32928 | T18: Alwar | U18: =COUNTIFS(Model!$J$2:$J$1001,$B$3,Model!$L$2:$L$1001,$B$4,Model!$I$2:$I$1001,$T18) -> 7 | V18: =SUMIFS(Model!$N$2:$N$1001,Model!$J$2:$J$1001,$B$3,Model!$L$2:$L$1001,$B$4,Model!$I$2:$I$1001,$T18) -> 18514 | W18: =$U18+$V18/1000000000+ROW()/1000000000000 -> 7.0000185 | AC18: C012 | AD18: =INDEX(Customers!$B$2:$B$101,MATCH($AC18,Customers!$A$2:$A$101,0)) -> Onkar Mangat | AE18: =SUMIFS(Model!$N$2:$N$1001,Model!$J$2:$J$1001,$B$3,Model!$L$2:$L$1001,$B$4,Model!$B$2:$B$1001,$AC18) -> 23591 | AF18: =COUNTIFS(Model!$J$2:$J$1001,$B$3,Model!$L$2:$L$1001,$B$4,Model!$B$2:$B$1001,$AC18) -> 8 | AG18: =$AE18+ROW()/1000000 -> 23591
L19: 13 | M19: =INDEX(Products!$B$2:$B$71,MATCH($L19,Products!$A$2:$A$71,0)) -> Et Set | N19: =SUMIFS(Model!$N$2:$N$1001,Model!$J$2:$J$1001,$B$3,Model!$L$2:$L$1001,$B$4,Model!$C$2:$C$1001,$L19) -> 69601 | O19: =$N19+ROW()/1000000 -> 69601 | T19: Amaravati | U19: =COUNTIFS(Model!$J$2:$J$1001,$B$3,Model!$L$2:$L$1001,$B$4,Model!$I$2:$I$1001,$T19) -> 2 | V19: =SUMIFS(Model!$N$2:$N$1001,Model!$J$2:$J$1001,$B$3,Model!$L$2:$L$1001,$B$4,Model!$I$2:$I$1001,$T19) -> 1891 | W19: =$U19+$V19/1000000000+ROW()/1000000000000 -> 2.0000019 | AC19: C013 | AD19: =INDEX(Customers!$B$2:$B$101,MATCH($AC19,Customers!$A$2:$A$101,0)) -> Manikya Goswami | AE19: =SUMIFS(Model!$N$2:$N$1001,Model!$J$2:$J$1001,$B$3,Model!$L$2:$L$1001,$B$4,Model!$B$2:$B$1001,$AC19) -> 46738 | AF19: =COUNTIFS(Model!$J$2:$J$1001,$B$3,Model!$L$2:$L$1001,$B$4,Model!$B$2:$B$1001,$AC19) -> 13 | AG19: =$AE19+ROW()/1000000 -> 46738
L20: 14 | M20: =INDEX(Products!$B$2:$B$71,MATCH($L20,Products!$A$2:$A$71,0)) -> Deserunt Box | N20: =SUMIFS(Model!$N$2:$N$1001,Model!$J$2:$J$1001,$B$3,Model!$L$2:$L$1001,$B$4,Model!$C$2:$C$1001,$L20) -> 97665 | O20: =$N20+ROW()/1000000 -> 97665 | T20: Ambala | U20: =COUNTIFS(Model!$J$2:$J$1001,$B$3,Model!$L$2:$L$1001,$B$4,Model!$I$2:$I$1001,$T20) -> 4 | V20: =SUMIFS(Model!$N$2:$N$1001,Model!$J$2:$J$1001,$B$3,Model!$L$2:$L$1001,$B$4,Model!$I$2:$I$1001,$T20) -> 18805 | W20: =$U20+$V20/1000000000+ROW()/1000000000000 -> 4.0000188 | AC20: C014 | AD20: =INDEX(Customers!$B$2:$B$101,MATCH($AC20,Customers!$A$2:$A$101,0)) -> Indrans Shukla | AE20: =SUMIFS(Model!$N$2:$N$1001,Model!$J$2:$J$1001,$B$3,Model!$L$2:$L$1001,$B$4,Model!$B$2:$B$1001,$AC20) -> 37235 | AF20: =COUNTIFS(Model!$J$2:$J$1001,$B$3,Model!$L$2:$L$1001,$B$4,Model!$B$2:$B$1001,$AC20) -> 12 | AG20: =$AE20+ROW()/1000000 -> 37235
A21: Revenue by occasion | L21: 15 | M21: =INDEX(Products!$B$2:$B$71,MATCH($L21,Products!$A$2:$A$71,0)) -> Repudiandae Box | N21: =SUMIFS(Model!$N$2:$N$1001,Model!$J$2:$J$1001,$B$3,Model!$L$2:$L$1001,$B$4,Model!$C$2:$C$1001,$L21) -> 44640 | O21: =$N21+ROW()/1000000 -> 44640 | T21: Ambarnath | U21: =COUNTIFS(Model!$J$2:$J$1001,$B$3,Model!$L$2:$L$1001,$B$4,Model!$I$2:$I$1001,$T21) -> 2 | V21: =SUMIFS(Model!$N$2:$N$1001,Model!$J$2:$J$1001,$B$3,Model!$L$2:$L$1001,$B$4,Model!$I$2:$I$1001,$T21) -> 7085 | W21: =$U21+$V21/1000000000+ROW()/1000000000000 -> 2.0000071 | AC21: C015 | AD21: =INDEX(Customers!$B$2:$B$101,MATCH($AC21,Customers!$A$2:$A$101,0)) -> Romil Bajwa | AE21: =SUMIFS(Model!$N$2:$N$1001,Model!$J$2:$J$1001,$B$3,Model!$L$2:$L$1001,$B$4,Model!$B$2:$B$1001,$AC21) -> 22045 | AF21: =COUNTIFS(Model!$J$2:$J$1001,$B$3,Model!$L$2:$L$1001,$B$4,Model!$B$2:$B$1001,$AC21) -> 9 | AG21: =$AE21+ROW()/1000000 -> 22045
A22: All Occasions | B22: =SUMIFS(Model!$N$2:$N$1001,Model!$J$2:$J$1001,$A22,Model!$J$2:$J$1001,$B$3,Model!$L$2:$L$1001,$B$4) -> 586176 | C22: =COUNTIFS(Model!$J$2:$J$1001,$A22,Model!$J$2:$J$1001,$B$3,Model!$L$2:$L$1001,$B$4) -> 126 | D22: =SUMIFS(Model!$D$2:$D$1001,Model!$J$2:$J$1001,$A22,Model!$J$2:$J$1001,$B$3,Model!$L$2:$L$1001,$B$4) -> 385 | E22: =IFERROR($B22/$C22,0) -> 4652.1905 | F22: =IFERROR(AVERAGEIFS(Model!$W$2:$W$1001,Model!$J$2:$J$1001,$A22,Model!$J$2:$J$1001,$B$3,Model!$L$2:$L$1001,$B$4),0) -> 5.6661117 | L22: 16 | M22: =INDEX(Products!$B$2:$B$71,MATCH($L22,Products!$A$2:$A$71,0)) -> Ut Pack | N22: =SUMIFS(Model!$N$2:$N$1001,Model!$J$2:$J$1001,$B$3,Model!$L$2:$L$1001,$B$4,Model!$C$2:$C$1001,$L22) -> 51630 | O22: =$N22+ROW()/1000000 -> 51630 | T22: Ambattur | U22: =COUNTIFS(Model!$J$2:$J$1001,$B$3,Model!$L$2:$L$1001,$B$4,Model!$I$2:$I$1001,$T22) -> 2 | V22: =SUMIFS(Model!$N$2:$N$1001,Model!$J$2:$J$1001,$B$3,Model!$L$2:$L$1001,$B$4,Model!$I$2:$I$1001,$T22) -> 1980 | W22: =$U22+$V22/1000000000+ROW()/1000000000000 -> 2.000002 | AC22: C016 | AD22: =INDEX(Customers!$B$2:$B$101,MATCH($AC22,Customers!$A$2:$A$101,0)) -> Amani Ganesh | AE22: =SUMIFS(Model!$N$2:$N$1001,Model!$J$2:$J$1001,$B$3,Model!$L$2:$L$1001,$B$4,Model!$B$2:$B$1001,$AC22) -> 37655 | AF22: =COUNTIFS(Model!$J$2:$J$1001,$B$3,Model!$L$2:$L$1001,$B$4,Model!$B$2:$B$1001,$AC22) -> 9 | AG22: =$AE22+ROW()/1000000 -> 37655
A23: Anniversary | B23: =SUMIFS(Model!$N$2:$N$1001,Model!$J$2:$J$1001,$A23,Model!$J$2:$J$1001,$B$3,Model!$L$2:$L$1001,$B$4) -> 674634 | C23: =COUNTIFS(Model!$J$2:$J$1001,$A23,Model!$J$2:$J$1001,$B$3,Model!$L$2:$L$1001,$B$4) -> 205 | D23: =SUMIFS(Model!$D$2:$D$1001,Model!$J$2:$J$1001,$A23,Model!$J$2:$J$1001,$B$3,Model!$L$2:$L$1001,$B$4) -> 607 | E23: =IFERROR($B23/$C23,0) -> 3290.8976 | F23: =IFERROR(AVERAGEIFS(Model!$W$2:$W$1001,Model!$J$2:$J$1001,$A23,Model!$J$2:$J$1001,$B$3,Model!$L$2:$L$1001,$B$4),0) -> 5.4929608 | L23: 17 | M23: =INDEX(Products!$B$2:$B$71,MATCH($L23,Products!$A$2:$A$71,0)) -> Delectus Gift | N23: =SUMIFS(Model!$N$2:$N$1001,Model!$J$2:$J$1001,$B$3,Model!$L$2:$L$1001,$B$4,Model!$C$2:$C$1001,$L23) -> 75960 | O23: =$N23+ROW()/1000000 -> 75960 | T23: Amravati | U23: =COUNTIFS(Model!$J$2:$J$1001,$B$3,Model!$L$2:$L$1001,$B$4,Model!$I$2:$I$1001,$T23) -> 5 | V23: =SUMIFS(Model!$N$2:$N$1001,Model!$J$2:$J$1001,$B$3,Model!$L$2:$L$1001,$B$4,Model!$I$2:$I$1001,$T23) -> 14444 | W23: =$U23+$V23/1000000000+ROW()/1000000000000 -> 5.0000144 | AC23: C017 | AD23: =INDEX(Customers!$B$2:$B$101,MATCH($AC23,Customers!$A$2:$A$101,0)) -> Advika Dhar | AE23: =SUMIFS(Model!$N$2:$N$1001,Model!$J$2:$J$1001,$B$3,Model!$L$2:$L$1001,$B$4,Model!$B$2:$B$1001,$AC23) -> 42855 | AF23: =COUNTIFS(Model!$J$2:$J$1001,$B$3,Model!$L$2:$L$1001,$B$4,Model!$B$2:$B$1001,$AC23) -> 9 | AG23: =$AE23+ROW()/1000000 -> 42855
A24: Birthday | B24: =SUMIFS(Model!$N$2:$N$1001,Model!$J$2:$J$1001,$A24,Model!$J$2:$J$1001,$B$3,Model!$L$2:$L$1001,$B$4) -> 408194 | C24: =COUNTIFS(Model!$J$2:$J$1001,$A24,Model!$J$2:$J$1001,$B$3,Model!$L$2:$L$1001,$B$4) -> 149 | D24: =SUMIFS(Model!$D$2:$D$1001,Model!$J$2:$J$1001,$A24,Model!$J$2:$J$1001,$B$3,Model!$L$2:$L$1001,$B$4) -> 438 | E24: =IFERROR($B24/$C24,0) -> 2739.557 | F24: =IFERROR(AVERAGEIFS(Model!$W$2:$W$1001,Model!$J$2:$J$1001,$A24,Model!$J$2:$J$1001,$B$3,Model!$L$2:$L$1001,$B$4),0) -> 5.4872314 | L24: 18 | M24: =INDEX(Products!$B$2:$B$71,MATCH($L24,Products!$A$2:$A$71,0)) -> Nemo Set | N24: =SUMIFS(Model!$N$2:$N$1001,Model!$J$2:$J$1001,$B$3,Model!$L$2:$L$1001,$B$4,Model!$C$2:$C$1001,$L24) -> 26554 | O24: =$N24+ROW()/1000000 -> 26554 | T24: Amritsar | U24: =COUNTIFS(Model!$J$2:$J$1001,$B$3,Model!$L$2:$L$1001,$B$4,Model!$I$2:$I$1001,$T24) -> 4 | V24: =SUMIFS(Model!$N$2:$N$1001,Model!$J$2:$J$1001,$B$3,Model!$L$2:$L$1001,$B$4,Model!$I$2:$I$1001,$T24) -> 15227 | W24: =$U24+$V24/1000000000+ROW()/1000000000000 -> 4.0000152 | AC24: C018 | AD24: =INDEX(Customers!$B$2:$B$101,MATCH($AC24,Customers!$A$2:$A$101,0)) -> Eva Vaidya | AE24: =SUMIFS(Model!$N$2:$N$1001,Model!$J$2:$J$1001,$B$3,Model!$L$2:$L$1001,$B$4,Model!$B$2:$B$1001,$AC24) -> 33717 | AF24: =COUNTIFS(Model!$J$2:$J$1001,$B$3,Model!$L$2:$L$1001,$B$4,Model!$B$2:$B$1001,$AC24) -> 11 | AG24: =$AE24+ROW()/1000000 -> 33717
A25: Diwali | B25: =SUMIFS(Model!$N$2:$N$1001,Model!$J$2:$J$1001,$A25,Model!$J$2:$J$1001,$B$3,Model!$L$2:$L$1001,$B$4) -> 313783 | C25: =COUNTIFS(Model!$J$2:$J$1001,$A25,Model!$J$2:$J$1001,$B$3,Model!$L$2:$L$1001,$B$4) -> 95 | D25: =SUMIFS(Model!$D$2:$D$1001,Model!$J$2:$J$1001,$A25,Model!$J$2:$J$1001,$B$3,Model!$L$2:$L$1001,$B$4) -> 297 | E25: =IFERROR($B25/$C25,0) -> 3302.9789 | F25: =IFERROR(AVERAGEIFS(Model!$W$2:$W$1001,Model!$J$2:$J$1001,$A25,Model!$J$2:$J$1001,$B$3,Model!$L$2:$L$1001,$B$4),0) -> 4.9551674 | L25: 19 | M25: =INDEX(Products!$B$2:$B$71,MATCH($L25,Products!$A$2:$A$71,0)) -> Iure Gift | N25: =SUMIFS(Model!$N$2:$N$1001,Model!$J$2:$J$1001,$B$3,Model!$L$2:$L$1001,$B$4,Model!$C$2:$C$1001,$L25) -> 51828 | O25: =$N25+ROW()/1000000 -> 51828 | T25: Amroha | U25: =COUNTIFS(Model!$J$2:$J$1001,$B$3,Model!$L$2:$L$1001,$B$4,Model!$I$2:$I$1001,$T25) -> 3 | V25: =SUMIFS(Model!$N$2:$N$1001,Model!$J$2:$J$1001,$B$3,Model!$L$2:$L$1001,$B$4,Model!$I$2:$I$1001,$T25) -> 5653 | W25: =$U25+$V25/1000000000+ROW()/1000000000000 -> 3.0000057 | AC25: C019 | AD25: =INDEX(Customers!$B$2:$B$101,MATCH($AC25,Customers!$A$2:$A$101,0)) -> Amira Sengupta | AE25: =SUMIFS(Model!$N$2:$N$1001,Model!$J$2:$J$1001,$B$3,Model!$L$2:$L$1001,$B$4,Model!$B$2:$B$1001,$AC25) -> 40031 | AF25: =COUNTIFS(Model!$J$2:$J$1001,$B$3,Model!$L$2:$L$1001,$B$4,Model!$B$2:$B$1001,$AC25) -> 9 | AG25: =$AE25+ROW()/1000000 -> 40031
A26: Holi | B26: =SUMIFS(Model!$N$2:$N$1001,Model!$J$2:$J$1001,$A26,Model!$J$2:$J$1001,$B$3,Model!$L$2:$L$1001,$B$4) -> 574682 | C26: =COUNTIFS(Model!$J$2:$J$1001,$A26,Model!$J$2:$J$1001,$B$3,Model!$L$2:$L$1001,$B$4) -> 180 | D26: =SUMIFS(Model!$D$2:$D$1001,Model!$J$2:$J$1001,$A26,Model!$J$2:$J$1001,$B$3,Model!$L$2:$L$1001,$B$4) -> 544 | E26: =IFERROR($B26/$C26,0) -> 3192.6778 | F26: =IFERROR(AVERAGEIFS(Model!$W$2:$W$1001,Model!$J$2:$J$1001,$A26,Model!$J$2:$J$1001,$B$3,Model!$L$2:$L$1001,$B$4),0) -> 5.7608106 | L26: 20 | M26: =INDEX(Products!$B$2:$B$71,MATCH($L26,Products!$A$2:$A$71,0)) -> Reiciendis Box | N26: =SUMIFS(Model!$N$2:$N$1001,Model!$J$2:$J$1001,$B$3,Model!$L$2:$L$1001,$B$4,Model!$C$2:$C$1001,$L26) -> 20910 | O26: =$N26+ROW()/1000000 -> 20910 | T26: Anand | U26: =COUNTIFS(Model!$J$2:$J$1001,$B$3,Model!$L$2:$L$1001,$B$4,Model!$I$2:$I$1001,$T26) -> 5 | V26: =SUMIFS(Model!$N$2:$N$1001,Model!$J$2:$J$1001,$B$3,Model!$L$2:$L$1001,$B$4,Model!$I$2:$I$1001,$T26) -> 8635 | W26: =$U26+$V26/1000000000+ROW()/1000000000000 -> 5.0000086 | AC26: C020 | AD26: =INDEX(Customers!$B$2:$B$101,MATCH($AC26,Customers!$A$2:$A$101,0)) -> Samaira Ganesh | AE26: =SUMIFS(Model!$N$2:$N$1001,Model!$J$2:$J$1001,$B$3,Model!$L$2:$L$1001,$B$4,Model!$B$2:$B$1001,$AC26) -> 75029 | AF26: =COUNTIFS(Model!$J$2:$J$1001,$B$3,Model!$L$2:$L$1001,$B$4,Model!$B$2:$B$1001,$AC26) -> 16 | AG26: =$AE26+ROW()/1000000 -> 75029
A27: Raksha Bandhan | B27: =SUMIFS(Model!$N$2:$N$1001,Model!$J$2:$J$1001,$A27,Model!$J$2:$J$1001,$B$3,Model!$L$2:$L$1001,$B$4) -> 631585 | C27: =COUNTIFS(Model!$J$2:$J$1001,$A27,Model!$J$2:$J$1001,$B$3,Model!$L$2:$L$1001,$B$4) -> 132 | D27: =SUMIFS(Model!$D$2:$D$1001,Model!$J$2:$J$1001,$A27,Model!$J$2:$J$1001,$B$3,Model!$L$2:$L$1001,$B$4) -> 424 | E27: =IFERROR($B27/$C27,0) -> 4784.7348 | F27: =IFERROR(AVERAGEIFS(Model!$W$2:$W$1001,Model!$J$2:$J$1001,$A27,Model!$J$2:$J$1001,$B$3,Model!$L$2:$L$1001,$B$4),0) -> 5.6439065 | L27: 21 | M27: =INDEX(Products!$B$2:$B$71,MATCH($L27,Products!$A$2:$A$71,0)) -> Quia Gift | N27: =SUMIFS(Model!$N$2:$N$1001,Model!$J$2:$J$1001,$B$3,Model!$L$2:$L$1001,$B$4,Model!$C$2:$C$1001,$L27) -> 68684 | O27: =$N27+ROW()/1000000 -> 68684 | T27: Anantapur | U27: =COUNTIFS(Model!$J$2:$J$1001,$B$3,Model!$L$2:$L$1001,$B$4,Model!$I$2:$I$1001,$T27) -> 1 | V27: =SUMIFS(Model!$N$2:$N$1001,Model!$J$2:$J$1001,$B$3,Model!$L$2:$L$1001,$B$4,Model!$I$2:$I$1001,$T27) -> 4515 | W27: =$U27+$V27/1000000000+ROW()/1000000000000 -> 1.0000045 | AC27: C021 | AD27: =INDEX(Customers!$B$2:$B$101,MATCH($AC27,Customers!$A$2:$A$101,0)) -> Siya Talwar | AE27: =SUMIFS(Model!$N$2:$N$1001,Model!$J$2:$J$1001,$B$3,Model!$L$2:$L$1001,$B$4,Model!$B$2:$B$1001,$AC27) -> 23641 | AF27: =COUNTIFS(Model!$J$2:$J$1001,$B$3,Model!$L$2:$L$1001,$B$4,Model!$B$2:$B$1001,$AC27) -> 6 | AG27: =$AE27+ROW()/1000000 -> 23641
A28: Valentine's Day | B28: =SUMIFS(Model!$N$2:$N$1001,Model!$J$2:$J$1001,$A28,Model!$J$2:$J$1001,$B$3,Model!$L$2:$L$1001,$B$4) -> 331930 | C28: =COUNTIFS(Model!$J$2:$J$1001,$A28,Model!$J$2:$J$1001,$B$3,Model!$L$2:$L$1001,$B$4) -> 113 | D28: =SUMIFS(Model!$D$2:$D$1001,Model!$J$2:$J$1001,$A28,Model!$J$2:$J$1001,$B$3,Model!$L$2:$L$1001,$B$4) -> 350 | E28: =IFERROR($B28/$C28,0) -> 2937.4336 | F28: =IFERROR(AVERAGEIFS(Model!$W$2:$W$1001,Model!$J$2:$J$1001,$A28,Model!$J$2:$J$1001,$B$3,Model!$L$2:$L$1001,$B$4),0) -> 5.2329181 | L28: 22 | M28: =INDEX(Products!$B$2:$B$71,MATCH($L28,Products!$A$2:$A$71,0)) -> Exercitationem Pack | N28: =SUMIFS(Model!$N$2:$N$1001,Model!$J$2:$J$1001,$B$3,Model!$L$2:$L$1001,$B$4,Model!$C$2:$C$1001,$L28) -> 96701 | O28: =$N28+ROW()/1000000 -> 96701 | T28: Anantapuram | U28: =COUNTIFS(Model!$J$2:$J$1001,$B$3,Model!$L$2:$L$1001,$B$4,Model!$I$2:$I$1001,$T28) -> 1 | V28: =SUMIFS(Model!$N$2:$N$1001,Model!$J$2:$J$1001,$B$3,Model!$L$2:$L$1001,$B$4,Model!$I$2:$I$1001,$T28) -> 7805 | W28: =$U28+$V28/1000000000+ROW()/1000000000000 -> 1.0000078 | AC28: C022 | AD28: =INDEX(Customers!$B$2:$B$101,MATCH($AC28,Customers!$A$2:$A$101,0)) -> Ivana Rout | AE28: =SUMIFS(Model!$N$2:$N$1001,Model!$J$2:$J$1001,$B$3,Model!$L$2:$L$1001,$B$4,Model!$B$2:$B$1001,$AC28) -> 40262 | AF28: =COUNTIFS(Model!$J$2:$J$1001,$B$3,Model!$L$2:$L$1001,$B$4,Model!$B$2:$B$1001,$AC28) -> 8 | AG28: =$AE28+ROW()/1000000 -> 40262
L29: 23 | M29: =INDEX(Products!$B$2:$B$71,MATCH($L29,Products!$A$2:$A$71,0)) -> Dignissimos Pack | N29: =SUMIFS(Model!$N$2:$N$1001,Model!$J$2:$J$1001,$B$3,Model!$L$2:$L$1001,$B$4,Model!$C$2:$C$1001,$L29) -> 90036 | O29: =$N29+ROW()/1000000 -> 90036 | T29: Arrah | U29: =COUNTIFS(Model!$J$2:$J$1001,$B$3,Model!$L$2:$L$1001,$B$4,Model!$I$2:$I$1001,$T29) -> 1 | V29: =SUMIFS(Model!$N$2:$N$1001,Model!$J$2:$J$1001,$B$3,Model!$L$2:$L$1001,$B$4,Model!$I$2:$I$1001,$T29) -> 1180 | W29: =$U29+$V29/1000000000+ROW()/1000000000000 -> 1.0000012 | AC29: C023 | AD29: =INDEX(Customers!$B$2:$B$101,MATCH($AC29,Customers!$A$2:$A$101,0)) -> Abram Sandhu | AE29: =SUMIFS(Model!$N$2:$N$1001,Model!$J$2:$J$1001,$B$3,Model!$L$2:$L$1001,$B$4,Model!$B$2:$B$1001,$AC29) -> 41112 | AF29: =COUNTIFS(Model!$J$2:$J$1001,$B$3,Model!$L$2:$L$1001,$B$4,Model!$B$2:$B$1001,$AC29) -> 10 | AG29: =$AE29+ROW()/1000000 -> 41112
L30: 24 | M30: =INDEX(Products!$B$2:$B$71,MATCH($L30,Products!$A$2:$A$71,0)) -> Ad Box | N30: =SUMIFS(Model!$N$2:$N$1001,Model!$J$2:$J$1001,$B$3,Model!$L$2:$L$1001,$B$4,Model!$C$2:$C$1001,$L30) -> 38520 | O30: =$N30+ROW()/1000000 -> 38520 | T30: Asansol | U30: =COUNTIFS(Model!$J$2:$J$1001,$B$3,Model!$L$2:$L$1001,$B$4,Model!$I$2:$I$1001,$T30) -> 3 | V30: =SUMIFS(Model!$N$2:$N$1001,Model!$J$2:$J$1001,$B$3,Model!$L$2:$L$1001,$B$4,Model!$I$2:$I$1001,$T30) -> 4945 | W30: =$U30+$V30/1000000000+ROW()/1000000000000 -> 3.0000049 | AC30: C024 | AD30: =INDEX(Customers!$B$2:$B$101,MATCH($AC30,Customers!$A$2:$A$101,0)) -> Jhanvi Chowdhury | AE30: =SUMIFS(Model!$N$2:$N$1001,Model!$J$2:$J$1001,$B$3,Model!$L$2:$L$1001,$B$4,Model!$B$2:$B$1001,$AC30) -> 59666 | AF30: =COUNTIFS(Model!$J$2:$J$1001,$B$3,Model!$L$2:$L$1001,$B$4,Model!$B$2:$B$1001,$AC30) -> 14 | AG30: =$AE30+ROW()/1000000 -> 59666
A31: Revenue by category | L31: 25 | M31: =INDEX(Products!$B$2:$B$71,MATCH($L31,Products!$A$2:$A$71,0)) -> Qui Gift | N31: =SUMIFS(Model!$N$2:$N$1001,Model!$J$2:$J$1001,$B$3,Model!$L$2:$L$1001,$B$4,Model!$C$2:$C$1001,$L31) -> 58898 | O31: =$N31+ROW()/1000000 -> 58898 | T31: Aurangabad | U31: =COUNTIFS(Model!$J$2:$J$1001,$B$3,Model!$L$2:$L$1001,$B$4,Model!$I$2:$I$1001,$T31) -> 4 | V31: =SUMIFS(Model!$N$2:$N$1001,Model!$J$2:$J$1001,$B$3,Model!$L$2:$L$1001,$B$4,Model!$I$2:$I$1001,$T31) -> 21817 | W31: =$U31+$V31/1000000000+ROW()/1000000000000 -> 4.0000218 | AC31: C025 | AD31: =INDEX(Customers!$B$2:$B$101,MATCH($AC31,Customers!$A$2:$A$101,0)) -> Ira Bava | AE31: =SUMIFS(Model!$N$2:$N$1001,Model!$J$2:$J$1001,$B$3,Model!$L$2:$L$1001,$B$4,Model!$B$2:$B$1001,$AC31) -> 26463 | AF31: =COUNTIFS(Model!$J$2:$J$1001,$B$3,Model!$L$2:$L$1001,$B$4,Model!$B$2:$B$1001,$AC31) -> 6 | AG31: =$AE31+ROW()/1000000 -> 26463
A32: Cake | B32: =SUMIFS(Model!$N$2:$N$1001,Model!$L$2:$L$1001,$A32,Model!$L$2:$L$1001,$B$4,Model!$J$2:$J$1001,$B$3) -> 329862 | C32: =COUNTIFS(Model!$L$2:$L$1001,$A32,Model!$L$2:$L$1001,$B$4,Model!$J$2:$J$1001,$B$3) -> 118 | D32: =SUMIFS(Model!$D$2:$D$1001,Model!$L$2:$L$1001,$A32,Model!$L$2:$L$1001,$B$4,Model!$J$2:$J$1001,$B$3) -> 375 | E32: =IFERROR($B32/$C32,0) -> 2795.4407 | L32: 26 | M32: =INDEX(Products!$B$2:$B$71,MATCH($L32,Products!$A$2:$A$71,0)) -> Aliquam Box | N32: =SUMIFS(Model!$N$2:$N$1001,Model!$J$2:$J$1001,$B$3,Model!$L$2:$L$1001,$B$4,Model!$C$2:$C$1001,$L32) -> 18785 | O32: =$N32+ROW()/1000000 -> 18785 | T32: Avadi | U32: =COUNTIFS(Model!$J$2:$J$1001,$B$3,Model!$L$2:$L$1001,$B$4,Model!$I$2:$I$1001,$T32) -> 5 | V32: =SUMIFS(Model!$N$2:$N$1001,Model!$J$2:$J$1001,$B$3,Model!$L$2:$L$1001,$B$4,Model!$I$2:$I$1001,$T32) -> 17069 | W32: =$U32+$V32/1000000000+ROW()/1000000000000 -> 5.0000171 | AC32: C026 | AD32: =INDEX(Customers!$B$2:$B$101,MATCH($AC32,Customers!$A$2:$A$101,0)) -> Ira Chahal | AE32: =SUMIFS(Model!$N$2:$N$1001,Model!$J$2:$J$1001,$B$3,Model!$L$2:$L$1001,$B$4,Model!$B$2:$B$1001,$AC32) -> 31319 | AF32: =COUNTIFS(Model!$J$2:$J$1001,$B$3,Model!$L$2:$L$1001,$B$4,Model!$B$2:$B$1001,$AC32) -> 9 | AG32: =$AE32+ROW()/1000000 -> 31319
A33: Colors | B33: =SUMIFS(Model!$N$2:$N$1001,Model!$L$2:$L$1001,$A33,Model!$L$2:$L$1001,$B$4,Model!$J$2:$J$1001,$B$3) -> 1005645 | C33: =COUNTIFS(Model!$L$2:$L$1001,$A33,Model!$L$2:$L$1001,$B$4,Model!$J$2:$J$1001,$B$3) -> 273 | D33: =SUMIFS(Model!$D$2:$D$1001,Model!$L$2:$L$1001,$A33,Model!$L$2:$L$1001,$B$4,Model!$J$2:$J$1001,$B$3) -> 810 | E33: =IFERROR($B33/$C33,0) -> 3683.6813 | L33: 27 | M33: =INDEX(Products!$B$2:$B$71,MATCH($L33,Products!$A$2:$A$71,0)) -> Architecto Gift | N33: =SUMIFS(Model!$N$2:$N$1001,Model!$J$2:$J$1001,$B$3,Model!$L$2:$L$1001,$B$4,Model!$C$2:$C$1001,$L33) -> 26852 | O33: =$N33+ROW()/1000000 -> 26852 | T33: Bahraich | U33: =COUNTIFS(Model!$J$2:$J$1001,$B$3,Model!$L$2:$L$1001,$B$4,Model!$I$2:$I$1001,$T33) -> 3 | V33: =SUMIFS(Model!$N$2:$N$1001,Model!$J$2:$J$1001,$B$3,Model!$L$2:$L$1001,$B$4,Model!$I$2:$I$1001,$T33) -> 10858 | W33: =$U33+$V33/1000000000+ROW()/1000000000000 -> 3.0000109 | AC33: C027 | AD33: =INDEX(Customers!$B$2:$B$101,MATCH($AC33,Customers!$A$2:$A$101,0)) -> Kashvi Sur | AE33: =SUMIFS(Model!$N$2:$N$1001,Model!$J$2:$J$1001,$B$3,Model!$L$2:$L$1001,$B$4,Model!$B$2:$B$1001,$AC33) -> 33149 | AF33: =COUNTIFS(Model!$J$2:$J$1001,$B$3,Model!$L$2:$L$1001,$B$4,Model!$B$2:$B$1001,$AC33) -> 8 | AG33: =$AE33+ROW()/1000000 -> 33149
A34: Mugs | B34: =SUMIFS(Model!$N$2:$N$1001,Model!$L$2:$L$1001,$A34,Model!$L$2:$L$1001,$B$4,Model!$J$2:$J$1001,$B$3) -> 201151 | C34: =COUNTIFS(Model!$L$2:$L$1001,$A34,Model!$L$2:$L$1001,$B$4,Model!$J$2:$J$1001,$B$3) -> 74 | D34: =SUMIFS(Model!$D$2:$D$1001,Model!$L$2:$L$1001,$A34,Model!$L$2:$L$1001,$B$4,Model!$J$2:$J$1001,$B$3) -> 232 | E34: =IFERROR($B34/$C34,0) -> 2718.2568 | L34: 28 | M34: =INDEX(Products!$B$2:$B$71,MATCH($L34,Products!$A$2:$A$71,0)) -> Velit Set | N34: =SUMIFS(Model!$N$2:$N$1001,Model!$J$2:$J$1001,$B$3,Model!$L$2:$L$1001,$B$4,Model!$C$2:$C$1001,$L34) -> 76454 | O34: =$N34+ROW()/1000000 -> 76454 | T34: Ballia | U34: =COUNTIFS(Model!$J$2:$J$1001,$B$3,Model!$L$2:$L$1001,$B$4,Model!$I$2:$I$1001,$T34) -> 6 | V34: =SUMIFS(Model!$N$2:$N$1001,Model!$J$2:$J$1001,$B$3,Model!$L$2:$L$1001,$B$4,Model!$I$2:$I$1001,$T34) -> 14299 | W34: =$U34+$V34/1000000000+ROW()/1000000000000 -> 6.0000143 | AC34: C028 | AD34: =INDEX(Customers!$B$2:$B$101,MATCH($AC34,Customers!$A$2:$A$101,0)) -> Hridaan Rajagopalan | AE34: =SUMIFS(Model!$N$2:$N$1001,Model!$J$2:$J$1001,$B$3,Model!$L$2:$L$1001,$B$4,Model!$B$2:$B$1001,$AC34) -> 37013 | AF34: =COUNTIFS(Model!$J$2:$J$1001,$B$3,Model!$L$2:$L$1001,$B$4,Model!$B$2:$B$1001,$AC34) -> 13 | AG34: =$AE34+ROW()/1000000 -> 37013
A35: Plants | B35: =SUMIFS(Model!$N$2:$N$1001,Model!$L$2:$L$1001,$A35,Model!$L$2:$L$1001,$B$4,Model!$J$2:$J$1001,$B$3) -> 212281 | C35: =COUNTIFS(Model!$L$2:$L$1001,$A35,Model!$L$2:$L$1001,$B$4,Model!$J$2:$J$1001,$B$3) -> 99 | D35: =SUMIFS(Model!$D$2:$D$1001,Model!$L$2:$L$1001,$A35,Model!$L$2:$L$1001,$B$4,Model!$J$2:$J$1001,$B$3) -> 306 | E35: =IFERROR($B35/$C35,0) -> 2144.2525 | L35: 29 | M35: =INDEX(Products!$B$2:$B$71,MATCH($L35,Products!$A$2:$A$71,0)) -> In Set | N35: =SUMIFS(Model!$N$2:$N$1001,Model!$J$2:$J$1001,$B$3,Model!$L$2:$L$1001,$B$4,Model!$C$2:$C$1001,$L35) -> 45072 | O35: =$N35+ROW()/1000000 -> 45072 | T35: Bally | U35: =COUNTIFS(Model!$J$2:$J$1001,$B$3,Model!$L$2:$L$1001,$B$4,Model!$I$2:$I$1001,$T35) -> 6 | V35: =SUMIFS(Model!$N$2:$N$1001,Model!$J$2:$J$1001,$B$3,Model!$L$2:$L$1001,$B$4,Model!$I$2:$I$1001,$T35) -> 23263 | W35: =$U35+$V35/1000000000+ROW()/1000000000000 -> 6.0000233 | AC35: C029 | AD35: =INDEX(Customers!$B$2:$B$101,MATCH($AC35,Customers!$A$2:$A$101,0)) -> Badal Sathe | AE35: =SUMIFS(Model!$N$2:$N$1001,Model!$J$2:$J$1001,$B$3,Model!$L$2:$L$1001,$B$4,Model!$B$2:$B$1001,$AC35) -> 46420 | AF35: =COUNTIFS(Model!$J$2:$J$1001,$B$3,Model!$L$2:$L$1001,$B$4,Model!$B$2:$B$1001,$AC35) -> 11 | AG35: =$AE35+ROW()/1000000 -> 46420
A36: Raksha Bandhan | B36: =SUMIFS(Model!$N$2:$N$1001,Model!$L$2:$L$1001,$A36,Model!$L$2:$L$1001,$B$4,Model!$J$2:$J$1001,$B$3) -> 297372 | C36: =COUNTIFS(Model!$L$2:$L$1001,$A36,Model!$L$2:$L$1001,$B$4,Model!$J$2:$J$1001,$B$3) -> 99 | D36: =SUMIFS(Model!$D$2:$D$1001,Model!$L$2:$L$1001,$A36,Model!$L$2:$L$1001,$B$4,Model!$J$2:$J$1001,$B$3) -> 278 | E36: =IFERROR($B36/$C36,0) -> 3003.7576 | L36: 30 | M36: =INDEX(Products!$B$2:$B$71,MATCH($L36,Products!$A$2:$A$71,0)) -> Recusandae Pack | N36: =SUMIFS(Model!$N$2:$N$1001,Model!$J$2:$J$1001,$B$3,Model!$L$2:$L$1001,$B$4,Model!$C$2:$C$1001,$L36) -> 33044 | O36: =$N36+ROW()/1000000 -> 33044 | T36: Bangalore | U36: =COUNTIFS(Model!$J$2:$J$1001,$B$3,Model!$L$2:$L$1001,$B$4,Model!$I$2:$I$1001,$T36) -> 4 | V36: =SUMIFS(Model!$N$2:$N$1001,Model!$J$2:$J$1001,$B$3,Model!$L$2:$L$1001,$B$4,Model!$I$2:$I$1001,$T36) -> 7930 | W36: =$U36+$V36/1000000000+ROW()/1000000000000 -> 4.0000079 | AC36: C030 | AD36: =INDEX(Customers!$B$2:$B$101,MATCH($AC36,Customers!$A$2:$A$101,0)) -> Vardaniya Contractor | AE36: =SUMIFS(Model!$N$2:$N$1001,Model!$J$2:$J$1001,$B$3,Model!$L$2:$L$1001,$B$4,Model!$B$2:$B$1001,$AC36) -> 48097 | AF36: =COUNTIFS(Model!$J$2:$J$1001,$B$3,Model!$L$2:$L$1001,$B$4,Model!$B$2:$B$1001,$AC36) -> 12 | AG36: =$AE36+ROW()/1000000 -> 48097
A37: Soft Toys | B37: =SUMIFS(Model!$N$2:$N$1001,Model!$L$2:$L$1001,$A37,Model!$L$2:$L$1001,$B$4,Model!$J$2:$J$1001,$B$3) -> 740831 | C37: =COUNTIFS(Model!$L$2:$L$1001,$A37,Model!$L$2:$L$1001,$B$4,Model!$J$2:$J$1001,$B$3) -> 166 | D37: =SUMIFS(Model!$D$2:$D$1001,Model!$L$2:$L$1001,$A37,Model!$L$2:$L$1001,$B$4,Model!$J$2:$J$1001,$B$3) -> 503 | E37: =IFERROR($B37/$C37,0) -> 4462.8373 | L37: 31 | M37: =INDEX(Products!$B$2:$B$71,MATCH($L37,Products!$A$2:$A$71,0)) -> Nihil Box | N37: =SUMIFS(Model!$N$2:$N$1001,Model!$J$2:$J$1001,$B$3,Model!$L$2:$L$1001,$B$4,Model!$C$2:$C$1001,$L37) -> 73964 | O37: =$N37+ROW()/1000000 -> 73964 | T37: Barasat | U37: =COUNTIFS(Model!$J$2:$J$1001,$B$3,Model!$L$2:$L$1001,$B$4,Model!$I$2:$I$1001,$T37) -> 4 | V37: =SUMIFS(Model!$N$2:$N$1001,Model!$J$2:$J$1001,$B$3,Model!$L$2:$L$1001,$B$4,Model!$I$2:$I$1001,$T37) -> 13565 | W37: =$U37+$V37/1000000000+ROW()/1000000000000 -> 4.0000136 | AC37: C031 | AD37: =INDEX(Customers!$B$2:$B$101,MATCH($AC37,Customers!$A$2:$A$101,0)) -> Madhup Wable | AE37: =SUMIFS(Model!$N$2:$N$1001,Model!$J$2:$J$1001,$B$3,Model!$L$2:$L$1001,$B$4,Model!$B$2:$B$1001,$AC37) -> 30814 | AF37: =COUNTIFS(Model!$J$2:$J$1001,$B$3,Model!$L$2:$L$1001,$B$4,Model!$B$2:$B$1001,$AC37) -> 9 | AG37: =$AE37+ROW()/1000000 -> 30814
A38: Sweets | B38: =SUMIFS(Model!$N$2:$N$1001,Model!$L$2:$L$1001,$A38,Model!$L$2:$L$1001,$B$4,Model!$J$2:$J$1001,$B$3) -> 733842 | C38: =COUNTIFS(Model!$L$2:$L$1001,$A38,Model!$L$2:$L$1001,$B$4,Model!$J$2:$J$1001,$B$3) -> 171 | D38: =SUMIFS(Model!$D$2:$D$1001,Model!$L$2:$L$1001,$A38,Model!$L$2:$L$1001,$B$4,Model!$J$2:$J$1001,$B$3) -> 541 | E38: =IFERROR($B38/$C38,0) -> 4291.4737 | L38: 32 | M38: =INDEX(Products!$B$2:$B$71,MATCH($L38,Products!$A$2:$A$71,0)) -> Fuga Set | N38: =SUMIFS(Model!$N$2:$N$1001,Model!$J$2:$J$1001,$B$3,Model!$L$2:$L$1001,$B$4,Model!$C$2:$C$1001,$L38) -> 80640 | O38: =$N38+ROW()/1000000 -> 80640 | T38: Bardhaman | U38: =COUNTIFS(Model!$J$2:$J$1001,$B$3,Model!$L$2:$L$1001,$B$4,Model!$I$2:$I$1001,$T38) -> 4 | V38: =SUMIFS(Model!$N$2:$N$1001,Model!$J$2:$J$1001,$B$3,Model!$L$2:$L$1001,$B$4,Model!$I$2:$I$1001,$T38) -> 11234 | W38: =$U38+$V38/1000000000+ROW()/1000000000000 -> 4.0000112 | AC38: C032 | AD38: =INDEX(Customers!$B$2:$B$101,MATCH($AC38,Customers!$A$2:$A$101,0)) -> Mannat Anand | AE38: =SUMIFS(Model!$N$2:$N$1001,Model!$J$2:$J$1001,$B$3,Model!$L$2:$L$1001,$B$4,Model!$B$2:$B$1001,$AC38) -> 49494 | AF38: =COUNTIFS(Model!$J$2:$J$1001,$B$3,Model!$L$2:$L$1001,$B$4,Model!$B$2:$B$1001,$AC38) -> 13 | AG38: =$AE38+ROW()/1000000 -> 49494
L39: 33 | M39: =INDEX(Products!$B$2:$B$71,MATCH($L39,Products!$A$2:$A$71,0)) -> Earum Set | N39: =SUMIFS(Model!$N$2:$N$1001,Model!$J$2:$J$1001,$B$3,Model!$L$2:$L$1001,$B$4,Model!$C$2:$C$1001,$L39) -> 13188 | O39: =$N39+ROW()/1000000 -> 13188 | T39: Bareilly | U39: =COUNTIFS(Model!$J$2:$J$1001,$B$3,Model!$L$2:$L$1001,$B$4,Model!$I$2:$I$1001,$T39) -> 9 | V39: =SUMIFS(Model!$N$2:$N$1001,Model!$J$2:$J$1001,$B$3,Model!$L$2:$L$1001,$B$4,Model!$I$2:$I$1001,$T39) -> 30626 | W39: =$U39+$V39/1000000000+ROW()/1000000000000 -> 9.0000306 | AC39: C033 | AD39: =INDEX(Customers!$B$2:$B$101,MATCH($AC39,Customers!$A$2:$A$101,0)) -> Suhana Kurian | AE39: =SUMIFS(Model!$N$2:$N$1001,Model!$J$2:$J$1001,$B$3,Model!$L$2:$L$1001,$B$4,Model!$B$2:$B$1001,$AC39) -> 32998 | AF39: =COUNTIFS(Model!$J$2:$J$1001,$B$3,Model!$L$2:$L$1001,$B$4,Model!$B$2:$B$1001,$AC39) -> 10 | AG39: =$AE39+ROW()/1000000 -> 32998
L40: 34 | M40: =INDEX(Products!$B$2:$B$71,MATCH($L40,Products!$A$2:$A$71,0)) -> Placeat Pack | N40: =SUMIFS(Model!$N$2:$N$1001,Model!$J$2:$J$1001,$B$3,Model!$L$2:$L$1001,$B$4,Model!$C$2:$C$1001,$L40) -> 53400 | O40: =$N40+ROW()/1000000 -> 53400 | T40: Bathinda | U40: =COUNTIFS(Model!$J$2:$J$1001,$B$3,Model!$L$2:$L$1001,$B$4,Model!$I$2:$I$1001,$T40) -> 3 | V40: =SUMIFS(Model!$N$2:$N$1001,Model!$J$2:$J$1001,$B$3,Model!$L$2:$L$1001,$B$4,Model!$I$2:$I$1001,$T40) -> 6390 | W40: =$U40+$V40/1000000000+ROW()/1000000000000 -> 3.0000064 | AC40: C034 | AD40: =INDEX(Customers!$B$2:$B$101,MATCH($AC40,Customers!$A$2:$A$101,0)) -> Hridaan Sood | AE40: =SUMIFS(Model!$N$2:$N$1001,Model!$J$2:$J$1001,$B$3,Model!$L$2:$L$1001,$B$4,Model!$B$2:$B$1001,$AC40) -> 33618 | AF40: =COUNTIFS(Model!$J$2:$J$1001,$B$3,Model!$L$2:$L$1001,$B$4,Model!$B$2:$B$1001,$AC40) -> 7 | AG40: =$AE40+ROW()/1000000 -> 33618
A41: Revenue by hour of order | L41: 35 | M41: =INDEX(Products!$B$2:$B$71,MATCH($L41,Products!$A$2:$A$71,0)) -> Nam Gift | N41: =SUMIFS(Model!$N$2:$N$1001,Model!$J$2:$J$1001,$B$3,Model!$L$2:$L$1001,$B$4,Model!$C$2:$C$1001,$L41) -> 91385 | O41: =$N41+ROW()/1000000 -> 91385 | T41: Begusarai | U41: =COUNTIFS(Model!$J$2:$J$1001,$B$3,Model!$L$2:$L$1001,$B$4,Model!$I$2:$I$1001,$T41) -> 3 | V41: =SUMIFS(Model!$N$2:$N$1001,Model!$J$2:$J$1001,$B$3,Model!$L$2:$L$1001,$B$4,Model!$I$2:$I$1001,$T41) -> 15425 | W41: =$U41+$V41/1000000000+ROW()/1000000000000 -> 3.0000154 | AC41: C035 | AD41: =INDEX(Customers!$B$2:$B$101,MATCH($AC41,Customers!$A$2:$A$101,0)) -> Ira Sarna | AE41: =SUMIFS(Model!$N$2:$N$1001,Model!$J$2:$J$1001,$B$3,Model!$L$2:$L$1001,$B$4,Model!$B$2:$B$1001,$AC41) -> 23064 | AF41: =COUNTIFS(Model!$J$2:$J$1001,$B$3,Model!$L$2:$L$1001,$B$4,Model!$B$2:$B$1001,$AC41) -> 10 | AG41: =$AE41+ROW()/1000000 -> 23064
...

Sheet Model
A1: Order_ID | B1: Customer_ID | C1: Product_ID | D1: Quantity | E1: Order_Date | F1: Order_Time | G1: Delivery_Date | H1: Delivery_Time | I1: Location | J1: Occasion | K1: Product_Name | L1: Category | M1: Unit_Price | N1: Revenue | O1: Buyer_City | P1: Gender | Q1: Customer_Name | R1: Month_No | S1: Month | T1: Hour | U1: Day_No | V1: Weekday | W1: Lead_Days | X1: Price_Band | Y1: Lead_Bucket
A2: 1 | B2: C037 | C2: 67 | D2: 5 | E2: 44981 | F2: 0.99181713 | G2: 44990 | H2: 0.31053241 | I2: Bardhaman | J2: Anniversary | K2: =INDEX(Products!$B$2:$B$71,MATCH($C2,Products!$A$2:$A$71,0)) -> Maiores Box | L2: =INDEX(Products!$C$2:$C$71,MATCH($C2,Products!$A$2:$A$71,0)) -> Raksha Bandhan | M2: =INDEX(Products!$D$2:$D$71,MATCH($C2,Products!$A$2:$A$71,0)) -> 1374 | N2: =$D2*$M2 -> 6870 | O2: =INDEX(Customers!$C$2:$C$101,MATCH($B2,Customers!$A$2:$A$101,0)) -> Davanagere | P2: =INDEX(Customers!$F$2:$F$101,MATCH($B2,Customers!$A$2:$A$101,0)) -> Male | Q2: =INDEX(Customers!$B$2:$B$101,MATCH($B2,Customers!$A$2:$A$101,0)) -> Aradhya Kumar | R2: =MONTH($E2) -> 2 | S2: =INDEX(Lists!$B$2:$B$13,$R2) -> February | T2: =HOUR($F2) -> 23 | U2: =WEEKDAY($E2,2) -> 5 | V2: =INDEX(Lists!$F$2:$F$8,$U2) -> Friday | W2: =($G2+$H2)-($E2+$F2) -> 8.3187153 | X2: =LOOKUP($M2,Lists!$G$2:$G$5,Lists!$H$2:$H$5) -> ₹1,000 - 1,499 | Y2: =LOOKUP($W2,Lists!$I$2:$I$7,Lists!$J$2:$J$7) -> 8 - 10 days
